Workbook
Name Céglista: Cégek[[#All],[Vevő név]]
Name Termekek: Terméklista!$A:$P
Name Vevő_név: Céglista!$A$2:$A$13

Sheet Új feladat
A1: Új | B1: Rendelés
A3: Customer | B3: Termék neve | C3: Megnevezése | D3: Megjegyzés | E3: Saját rendelési szám | F3: Anyag | G3: Rendelési szám | H3: Amount/pc | I3: Order date (y/m/) | J3: Required delivery date (y/m/d)
F4: =IFERROR(IF(_xlfn.XLOOKUP(B4,Terméklista!$B$2:$B$103,Terméklista!$G$2:$G$103)="","",_xlfn.XLOOKUP(B4,Terméklista!$B$2:$B$103,Terméklista!$G$2:$G$103)),"")
F5: =IFERROR(IF(_xlfn.XLOOKUP(B5,Terméklista!$B$2:$B$103,Terméklista!$G$2:$G$103)="","",_xlfn.XLOOKUP(B5,Terméklista!$B$2:$B$103,Terméklista!$G$2:$G$103)),"")
F6: =IFERROR(IF(_xlfn.XLOOKUP(B6,Terméklista!$B$2:$B$103,Terméklista!$G$2:$G$103)="","",_xlfn.XLOOKUP(B6,Terméklista!$B$2:$B$103,Terméklista!$G$2:$G$103)),"")
F7: =IFERROR(IF(_xlfn.XLOOKUP(B7,Terméklista!$B$2:$B$103,Terméklista!$G$2:$G$103)="","",_xlfn.XLOOKUP(B7,Terméklista!$B$2:$B$103,Terméklista!$G$2:$G$103)),"")
F8: =IFERROR(IF(_xlfn.XLOOKUP(B8,Terméklista!$B$2:$B$103,Terméklista!$G$2:$G$103)="","",_xlfn.XLOOKUP(B8,Terméklista!$B$2:$B$103,Terméklista!$G$2:$G$103)),"")
F9: =IFERROR(IF(_xlfn.XLOOKUP(B9,Terméklista!$B$2:$B$103,Terméklista!$G$2:$G$103)="","",_xlfn.XLOOKUP(B9,Terméklista!$B$2:$B$103,Terméklista!$G$2:$G$103)),"")
F10: =IFERROR(IF(_xlfn.XLOOKUP(B10,Terméklista!$B$2:$B$103,Terméklista!$G$2:$G$103)="","",_xlfn.XLOOKUP(B10,Terméklista!$B$2:$B$103,Terméklista!$G$2:$G$103)),"")
F11: =IFERROR(IF(_xlfn.XLOOKUP(B11,Terméklista!$B$2:$B$103,Terméklista!$G$2:$G$103)="","",_xlfn.XLOOKUP(B11,Terméklista!$B$2:$B$103,Terméklista!$G$2:$G$103)),"")
A13: Meglévő | B13: Rendelés
A15: Customer | B15: Termék neve | C15: Megnevezése | D15: Megjegyzés | E15: Saját rendelési szám | F15: Anyag | G15: Rendelési szám | H15: Amount/pc | I15: Order date (y/m/) | J15: Required delivery date (y/m/d)
A21: Új | B21: Termék
A22: Ügyfél | B22: Termék megnevezés | C22: Termék rajzszáma | D22: Megjegyzés | E22: Fészekszáma | F22: Súly/db g | G22: Anyag | H22: Felületkezelés | I22: Ciklus idő | J22: Utómunka idő | K22: Utómunkák | L22: Doboz méret | M22: Doboz/db | N22: Doboz/Raklap | O22: Arktikál nr. | P22: Raktár | Q22: Engusz súly
A27: Új | B27: Cég
A29: Vevő név | B29: Szállító Nyelve | C29: Város | D29: Irányítószám | E29: Utca, házszám | F29: Ország | G29: Cím | H29: Adószám | I29: Vevő név
G30: =CONCATENATE(D30," ",C30,", ",E30) -> ,

Sheet Rendelés
A1: Megrendelési információ | R1: =SUM(Rendelés[Szükséges anyagmennyiség]) -> #N/A
A2: Customer | B2: Termék neve | C2: Megnevezése | D2: Megjegyzés | E2: Saját rendelési szám | F2: Anyag | G2: Rendelési szám | H2: Amount/pc | I2: Order date (year/month/day) | J2: Required delivery date (year/month/day) | K2: Actual pickup date (year/month/day) | L2: Számlázva (x) | M2: Szállításra kész | N2: Felületkezelés | O2: Dobozok száma | P2: Össz raklapok száma | Q2: Össz bruttó súly | R2: Szükséges anyagmennyiség | S2: Tervezett gyártási idő | T2: Szállítólevél | U2: Státusz
A3: Systec Pos-Technology Gmbh | B3: Smartstop-2 Rasthebel-2 | C3: =IFERROR(_xlfn.XLOOKUP(B3,Terméklista!$B$2:$B$103,Terméklista!$C$2:$C$103,)," ") | E3: M251001 | F3: =_xlfn.XLOOKUP(B3,Terméklista!$B$2:$B$103,Terméklista!$G$2:$G$103," ") | G3: 26287 | H3: 10000 | I3: 2024-11-18 | J3: 2025-01-28 | K3: 2025-01-21 | L3: x | N3: =IFERROR(_xlfn.XLOOKUP(B3,Terméklista!B2:B103,Terméklista!H2:H103)," ") | O3: =IFERROR(ROUNDUP(Rendelés[[#This Row],[Amount/pc]]/_xlfn.XLOOKUP(B3,Terméklista!$B$2:$B$103,Terméklista!$M$2:$M$103,),0)," ") | P3: =IFERROR(ROUNDUP(Rendelés[[#This Row],[Dobozok száma]]/_xlfn.XLOOKUP(B3,Terméklista!$B$2:$B$103,Terméklista!$N$2:$N$103,),0)," ") | Q3: =IFERROR(Rendelés[[#This Row],[Szükséges anyagmennyiség]]+(Rendelés[[#This Row],[Össz raklapok száma]]*25),"") | R3: {=(H3*_xlfn.XLOOKUP(B3,Terméklista!$B$2:$B$103,Terméklista!F$2:$F$103,))/1000} -> #N/A | S3: =IFERROR(((H3/_xlfn.XLOOKUP(B3,Terméklista!$B$2:$B$103,Terméklista!$E$2:$E$103)*_xlfn.XLOOKUP(B3,Terméklista!$B$2:$B$103,Terméklista!$I$2:$I$103)))/3600," ")
A4: Seidel Gmbh&co Kg | B4: MA41 | C4: =IFERROR(_xlfn.XLOOKUP(B4,Terméklista!$B$2:$B$103,Terméklista!$C$2:$C$103,)," ") -> Zamak Gewicht | E4: M251017 | F4: =_xlfn.XLOOKUP(B4,Terméklista!$B$2:$B$103,Terméklista!$G$2:$G$103," ") -> Z410 | G4: 4500099245 | H4: 75000 | I4: 2024-11-25 | J4: 2025-02-03 | K4: 2025-02-18 | L4: x | N4: =IFERROR(_xlfn.XLOOKUP(B4,Terméklista!B18:B119,Terméklista!H18:H119)," ") -> 0 | O4: =IFERROR(ROUNDUP(Rendelés[[#This Row],[Amount/pc]]/_xlfn.XLOOKUP(B4,Terméklista!$B$2:$B$103,Terméklista!$M$2:$M$103,),0)," ") -> 215 | P4: =IFERROR(ROUNDUP(Rendelés[[#This Row],[Dobozok száma]]/_xlfn.XLOOKUP(B4,Terméklista!$B$2:$B$103,Terméklista!$N$2:$N$103,),0)," ") -> 3 | Q4: =IFERROR(Rendelés[[#This Row],[Szükséges anyagmennyiség]]+(Rendelés[[#This Row],[Össz raklapok száma]]*25),"") -> 1350 | R4: {=(H4*_xlfn.XLOOKUP(B4,Terméklista!$B$2:$B$103,Terméklista!F$2:$F$103,))/1000} -> 1275 | S4: =IFERROR(((H4/_xlfn.XLOOKUP(B4,Terméklista!$B$2:$B$103,Terméklista!$E$2:$E$103)*_xlfn.XLOOKUP(B4,Terméklista!$B$2:$B$103,Terméklista!$I$2:$I$103)))/3600," ") -> 52.083333
A5: Seidel Gmbh&co Kg | B5: MA66 | C5: =IFERROR(_xlfn.XLOOKUP(B5,Terméklista!$B$2:$B$103,Terméklista!$C$2:$C$103,)," ") -> Zamak Gewicht | E5: M251002 | F5: =_xlfn.XLOOKUP(B5,Terméklista!$B$2:$B$103,Terméklista!$G$2:$G$103," ") -> Z410 | G5: 4500099503 | H5: 100000 | I5: 2024-12-12 | J5: 2025-02-13 | K5: 2025-03-06 | L5: x | N5: =IFERROR(_xlfn.XLOOKUP(B5,Terméklista!B3:B104,Terméklista!H3:H104)," ") -> 0 | O5: =IFERROR(ROUNDUP(Rendelés[[#This Row],[Amount/pc]]/_xlfn.XLOOKUP(B5,Terméklista!$B$2:$B$103,Terméklista!$M$2:$M$103,),0)," ") -> 200 | P5: =IFERROR(ROUNDUP(Rendelés[[#This Row],[Dobozok száma]]/_xlfn.XLOOKUP(B5,Terméklista!$B$2:$B$103,Terméklista!$N$2:$N$103,),0)," ") -> 3 | Q5: =IFERROR(Rendelés[[#This Row],[Szükséges anyagmennyiség]]+(Rendelés[[#This Row],[Össz raklapok száma]]*25),"") -> 1125 | R5: {=(H5*_xlfn.XLOOKUP(B5,Terméklista!$B$2:$B$103,Terméklista!F$2:$F$103,))/1000} -> 1050 | S5: =IFERROR(((H5/_xlfn.XLOOKUP(B5,Terméklista!$B$2:$B$103,Terméklista!$E$2:$E$103)*_xlfn.XLOOKUP(B5,Terméklista!$B$2:$B$103,Terméklista!$I$2:$I$103)))/3600," ") -> 69.444444
A6: Seidel Gmbh&co Kg | B6: MA41 | C6: =IFERROR(_xlfn.XLOOKUP(B6,Terméklista!$B$2:$B$103,Terméklista!$C$2:$C$103,)," ") -> Zamak Gewicht | E6: M251003 | F6: =_xlfn.XLOOKUP(B6,Terméklista!$B$2:$B$103,Terméklista!$G$2:$G$103," ") -> Z410 | G6: 4500099546 | H6: 50000 | I6: 2024-12-16 | J6: 2025-03-31 | L6: x | N6: =IFERROR(_xlfn.XLOOKUP(B6,Terméklista!B4:B105,Terméklista!H4:H105)," ") -> 0 | O6: =IFERROR(ROUNDUP(Rendelés[[#This Row],[Amount/pc]]/_xlfn.XLOOKUP(B6,Terméklista!$B$2:$B$103,Terméklista!$M$2:$M$103,),0)," ") -> 143 | P6: =IFERROR(ROUNDUP(Rendelés[[#This Row],[Dobozok száma]]/_xlfn.XLOOKUP(B6,Terméklista!$B$2:$B$103,Terméklista!$N$2:$N$103,),0)," ") -> 2 | Q6: =IFERROR(Rendelés[[#This Row],[Szükséges anyagmennyiség]]+(Rendelés[[#This Row],[Össz raklapok száma]]*25),"") -> 900 | R6: {=(H6*_xlfn.XLOOKUP(B6,Terméklista!$B$2:$B$103,Terméklista!F$2:$F$103,))/1000} -> 850 | S6: =IFERROR(((H6/_xlfn.XLOOKUP(B6,Terméklista!$B$2:$B$103,Terméklista!$E$2:$E$103)*_xlfn.XLOOKUP(B6,Terméklista!$B$2:$B$103,Terméklista!$I$2:$I$103)))/3600," ") -> 34.722222 | T6: 2025/23
A7: Ela Solutions Kft. | B7: 90ZA-ZK011-06 | C7: =IFERROR(_xlfn.XLOOKUP(B7,Terméklista!$B$2:$B$103,Terméklista!$C$2:$C$103,)," ") -> nagykulcs - 3mm | E7: M251004 | F7: =_xlfn.XLOOKUP(B7,Terméklista!$B$2:$B$103,Terméklista!$G$2:$G$103," ") -> Z410 | G7: 5491 | H7: 1000 | I7: 2025-01-06 | J7: 2025-01-08 | K7: 2025-01-09 | L7: x | N7: =IFERROR(_xlfn.XLOOKUP(B7,Terméklista!B5:B106,Terméklista!H5:H106)," ") -> 0 | O7: =IFERROR(ROUNDUP(Rendelés[[#This Row],[Amount/pc]]/_xlfn.XLOOKUP(B7,Terméklista!$B$2:$B$103,Terméklista!$M$2:$M$103,),0)," ") | P7: =IFERROR(ROUNDUP(Rendelés[[#This Row],[Dobozok száma]]/_xlfn.XLOOKUP(B7,Terméklista!$B$2:$B$103,Terméklista!$N$2:$N$103,),0)," ") | Q7: =IFERROR(Rendelés[[#This Row],[Szükséges anyagmennyiség]]+(Rendelés[[#This Row],[Össz raklapok száma]]*25),"") | R7: {=(H7*_xlfn.XLOOKUP(B7,Terméklista!$B$2:$B$103,Terméklista!F$2:$F$103,))/1000} -> 47.55 | S7: =IFERROR(((H7/_xlfn.XLOOKUP(B7,Terméklista!$B$2:$B$103,Terméklista!$E$2:$E$103)*_xlfn.XLOOKUP(B7,Terméklista!$B$2:$B$103,Terméklista!$I$2:$I$103)))/3600," ") -> 2.0833333
A8: Ela Solutions Kft. | B8: 90ZA-ZK011-06 | C8: =IFERROR(_xlfn.XLOOKUP(B8,Terméklista!$B$2:$B$103,Terméklista!$C$2:$C$103,)," ") -> nagykulcs - 3mm | E8: M251005 | F8: =_xlfn.XLOOKUP(B8,Terméklista!$B$2:$B$103,Terméklista!$G$2:$G$103," ") -> Z410 | G8: 5505 | H8: 1500 | I8: 2025-01-13 | J8: 2025-02-03 | K8: 2025-02-03 | L8: x | N8: =IFERROR(_xlfn.XLOOKUP(B8,Terméklista!B6:B107,Terméklista!H6:H107)," ") -> 0 | O8: =IFERROR(ROUNDUP(Rendelés[[#This Row],[Amount/pc]]/_xlfn.XLOOKUP(B8,Terméklista!$B$2:$B$103,Terméklista!$M$2:$M$103,),0)," ") | P8: =IFERROR(ROUNDUP(Rendelés[[#This Row],[Dobozok száma]]/_xlfn.XLOOKUP(B8,Terméklista!$B$2:$B$103,Terméklista!$N$2:$N$103,),0)," ") | Q8: =IFERROR(Rendelés[[#This Row],[Szükséges anyagmennyiség]]+(Rendelés[[#This Row],[Össz raklapok száma]]*30),"") | R8: {=(H8*_xlfn.XLOOKUP(B8,Terméklista!$B$2:$B$103,Terméklista!F$2:$F$103,))/1000} -> 71.325 | S8: =IFERROR(((H8/_xlfn.XLOOKUP(B8,Terméklista!$B$2:$B$103,Terméklista!$E$2:$E$103)*_xlfn.XLOOKUP(B8,Terméklista!$B$2:$B$103,Terméklista!$I$2:$I$103)))/3600," ") -> 3.125
A9: Seidel Gmbh&co Kg | B9: M83 | C9: =IFERROR(_xlfn.XLOOKUP(B9,Terméklista!$B$2:$B$103,Terméklista!$C$2:$C$103,)," ") -> Zamak Gewicht | E9: M251006 | F9: =_xlfn.XLOOKUP(B9,Terméklista!$B$2:$B$103,Terméklista!$G$2:$G$103," ") -> Z410 | G9: 4500099767 | H9: 70000 | I9: 2025-01-14 | J9: 2025-04-02 | K9: 2025-04-03 | L9: x | N9: =IFERROR(_xlfn.XLOOKUP(B9,Terméklista!B7:B108,Terméklista!H7:H108)," ") -> 0 | O9: =IFERROR(ROUNDUP(Rendelés[[#This Row],[Amount/pc]]/_xlfn.XLOOKUP(B9,Terméklista!$B$2:$B$103,Terméklista!$M$2:$M$103,),0)," ") -> 467 | P9: =IFERROR(ROUNDUP(Rendelés[[#This Row],[Dobozok száma]]/_xlfn.XLOOKUP(B9,Terméklista!$B$2:$B$103,Terméklista!$N$2:$N$103,),0)," ") -> 16 | Q9: =IFERROR(Rendelés[[#This Row],[Szükséges anyagmennyiség]]+(Rendelés[[#This Row],[Össz raklapok száma]]*30),"") -> 5051 | R9: {=(H9*_xlfn.XLOOKUP(B9,Terméklista!$B$2:$B$103,Terméklista!F$2:$F$103,))/1000} -> 4571 | S9: =IFERROR(((H9/_xlfn.XLOOKUP(B9,Terméklista!$B$2:$B$103,Terméklista!$E$2:$E$103)*_xlfn.XLOOKUP(B9,Terméklista!$B$2:$B$103,Terméklista!$I$2:$I$103)))/3600," ") -> 97.222222 | T9: 2025/27
A10: Arsisco AMO Pack LLC | B10: Fehér hüvely | C10: =IFERROR(_xlfn.XLOOKUP(B10,Terméklista!$B$2:$B$103,Terméklista!$C$2:$C$103,)," ") -> 0 | E10: M251007 | F10: =_xlfn.XLOOKUP(B10,Terméklista!$B$2:$B$103,Terméklista!$G$2:$G$103," ") -> Műanyag | G10: email: 21.01.2025 | H10: 360000 | I10: 2025-01-21 | J10: 2025-02-28 | K10: 2025-06-10 | L10: x | N10: =_xlfn.XLOOKUP(J10,Terméklista!$B$2:$B$103,Terméklista!$H$2:$H$103," ") | O10: =IFERROR(ROUNDUP(Rendelés[[#This Row],[Amount/pc]]/_xlfn.XLOOKUP(B10,Terméklista!$B$2:$B$103,Terméklista!$M$2:$M$103,),0)," ") | P10: =IFERROR(ROUNDUP(Rendelés[[#This Row],[Dobozok száma]]/_xlfn.XLOOKUP(B10,Terméklista!$B$2:$B$103,Terméklista!$N$2:$N$103,),0)," ") | Q10: =IFERROR(Rendelés[[#This Row],[Szükséges anyagmennyiség]]+(Rendelés[[#This Row],[Össz raklapok száma]]*25),"") | R10: {=(H10*_xlfn.XLOOKUP(B10,Terméklista!$B$2:$B$203,Terméklista!F$2:$F$203,))/1000} -> 81 | S10: =IFERROR(((H10/_xlfn.XLOOKUP(B10,Terméklista!$B$2:$B$103,Terméklista!$E$2:$E$103)*_xlfn.XLOOKUP(B10,Terméklista!$B$2:$B$103,Terméklista!$I$2:$I$103)))/3600," ") -> 325
A11: Ela Solutions Kft. | B11: 90ZA-B0011-06 | C11: =IFERROR(_xlfn.XLOOKUP(B11,Terméklista!$B$2:$B$103,Terméklista!$C$2:$C$103,)," ") -> 0 | E11: M251008 | F11: =_xlfn.XLOOKUP(B11,Terméklista!$B$2:$B$103,Terméklista!$G$2:$G$103," ") -> Z410 | G11: 5526 | H11: 150 | I11: 2025-01-21 | J11: 2025-01-22 | K11: 2025-01-22 | L11: x | N11: =IFERROR(_xlfn.XLOOKUP(B11,Terméklista!B9:B110,Terméklista!H9:H110)," ") -> 0 | O11: =IFERROR(ROUNDUP(Rendelés[[#This Row],[Amount/pc]]/_xlfn.XLOOKUP(B11,Terméklista!$B$2:$B$103,Terméklista!$M$2:$M$103,),0)," ") | P11: =IFERROR(ROUNDUP(Rendelés[[#This Row],[Dobozok száma]]/_xlfn.XLOOKUP(B11,Terméklista!$B$2:$B$103,Terméklista!$N$2:$N$103,),0)," ") | Q11: =IFERROR(Rendelés[[#This Row],[Szükséges anyagmennyiség]]+(Rendelés[[#This Row],[Össz raklapok száma]]*25),"") | R11: {=(H11*_xlfn.XLOOKUP(B11,Terméklista!$B$2:$B$103,Terméklista!F$2:$F$103,))/1000} -> 0.4335 | S11: =IFERROR(((H11/_xlfn.XLOOKUP(B11,Terméklista!$B$2:$B$103,Terméklista!$E$2:$E$103)*_xlfn.XLOOKUP(B11,Terméklista!$B$2:$B$103,Terméklista!$I$2:$I$103)))/3600," ") | T11: 2025/24
A12: Ela Solutions Kft. | B12: 90ZA-ZK001-06 | C12: =IFERROR(_xlfn.XLOOKUP(B12,Terméklista!$B$2:$B$103,Terméklista!$C$2:$C$103,)," ") -> 0 | E12: M251009 | F12: =_xlfn.XLOOKUP(B12,Terméklista!$B$2:$B$103,Terméklista!$G$2:$G$103," ") -> Z410 | G12: 5526 | H12: 500 | I12: 2025-01-21 | J12: 2025-01-22 | K12: 2025-01-22 | L12: x | N12: =IFERROR(_xlfn.XLOOKUP(B12,Terméklista!B10:B111,Terméklista!H10:H111)," ") -> 0 | O12: =IFERROR(ROUNDUP(Rendelés[[#This Row],[Amount/pc]]/_xlfn.XLOOKUP(B12,Terméklista!$B$2:$B$103,Terméklista!$M$2:$M$103,),0)," ") | P12: =IFERROR(ROUNDUP(Rendelés[[#This Row],[Dobozok száma]]/_xlfn.XLOOKUP(B12,Terméklista!$B$2:$B$103,Terméklista!$N$2:$N$103,),0)," ") | Q12: =IFERROR(Rendelés[[#This Row],[Szükséges anyagmennyiség]]+(Rendelés[[#This Row],[Össz raklapok száma]]*25),"") | R12: {=(H12*_xlfn.XLOOKUP(B12,Terméklista!$B$2:$B$103,Terméklista!F$2:$F$103,))/1000} -> 11.17 | S12: =IFERROR(((H12/_xlfn.XLOOKUP(B12,Terméklista!$B$2:$B$103,Terméklista!$E$2:$E$103)*_xlfn.XLOOKUP(B12,Terméklista!$B$2:$B$103,Terméklista!$I$2:$I$103)))/3600," ") -> 1.0416667
A13: Ela Solutions Kft. | B13: 90ZA-ZS001-06 | C13: =IFERROR(_xlfn.XLOOKUP(B13,Terméklista!$B$2:$B$103,Terméklista!$C$2:$C$103,)," ") -> Zsanérbelső | E13: M251010 | F13: =_xlfn.XLOOKUP(B13,Terméklista!$B$2:$B$103,Terméklista!$G$2:$G$103," ") -> Z410 | G13: 5526 | H13: 1000 | I13: 2025-01-21 | J13: 2025-01-22 | K13: 2025-01-22 | L13: x | N13: =IFERROR(_xlfn.XLOOKUP(B13,Terméklista!B11:B112,Terméklista!H11:H112)," ") -> 0 | O13: =IFERROR(ROUNDUP(Rendelés[[#This Row],[Amount/pc]]/_xlfn.XLOOKUP(B13,Terméklista!$B$2:$B$103,Terméklista!$M$2:$M$103,),0)," ") | P13: =IFERROR(ROUNDUP(Rendelés[[#This Row],[Dobozok száma]]/_xlfn.XLOOKUP(B13,Terméklista!$B$2:$B$103,Terméklista!$N$2:$N$103,),0)," ") | Q13: =IFERROR(Rendelés[[#This Row],[Szükséges anyagmennyiség]]+(Rendelés[[#This Row],[Össz raklapok száma]]*25),"") | R13: {=(H13*_xlfn.XLOOKUP(B13,Terméklista!$B$2:$B$103,Terméklista!F$2:$F$103,))/1000} -> 15 | S13: =IFERROR(((H13/_xlfn.XLOOKUP(B13,Terméklista!$B$2:$B$103,Terméklista!$E$2:$E$103)*_xlfn.XLOOKUP(B13,Terméklista!$B$2:$B$103,Terméklista!$I$2:$I$103)))/3600," ") -> 2.0833333
A14: Ela Solutions Kft. | B14: 90ZA-ZS002-06 | C14: =IFERROR(_xlfn.XLOOKUP(B14,Terméklista!$B$2:$B$103,Terméklista!$C$2:$C$103,)," ") -> Zsanérkülső | E14: M251011 | F14: =_xlfn.XLOOKUP(B14,Terméklista!$B$2:$B$103,Terméklista!$G$2:$G$103," ") -> Z410 | G14: 5526 | H14: 1000 | I14: 2025-01-21 | J14: 2025-01-22 | K14: 2025-01-22 | L14: x | N14: =IFERROR(_xlfn.XLOOKUP(B14,Terméklista!B12:B113,Terméklista!H12:H113)," ") -> 0 | O14: =IFERROR(ROUNDUP(Rendelés[[#This Row],[Amount/pc]]/_xlfn.XLOOKUP(B14,Terméklista!$B$2:$B$103,Terméklista!$M$2:$M$103,),0)," ") | P14: =IFERROR(ROUNDUP(Rendelés[[#This Row],[Dobozok száma]]/_xlfn.XLOOKUP(B14,Terméklista!$B$2:$B$103,Terméklista!$N$2:$N$103,),0)," ") | Q14: =IFERROR(Rendelés[[#This Row],[Szükséges anyagmennyiség]]+(Rendelés[[#This Row],[Össz raklapok száma]]*25),"") | R14: {=(H14*_xlfn.XLOOKUP(B14,Terméklista!$B$2:$B$103,Terméklista!F$2:$F$103,))/1000} -> 20.8 | S14: =IFERROR(((H14/_xlfn.XLOOKUP(B14,Terméklista!$B$2:$B$103,Terméklista!$E$2:$E$103)*_xlfn.XLOOKUP(B14,Terméklista!$B$2:$B$103,Terméklista!$I$2:$I$103)))/3600," ") -> 2.0833333 | T14: 2025/22
A15: Arsisco AMO Pack LLC | B15: Fehér hüvely | C15: =IFERROR(_xlfn.XLOOKUP(B15,Terméklista!$B$2:$B$103,Terméklista!$C$2:$C$103,)," ") -> 0 | E15: M251031 | F15: =_xlfn.XLOOKUP(B15,Terméklista!$B$2:$B$103,Terméklista!$G$2:$G$103," ") -> Műanyag | G15: email: 21.01.2025 | H15: 140000 | I15: 2025-01-21 | K15: 2025-03-19 | L15: x | N15: =IFERROR(_xlfn.XLOOKUP(B15,Terméklista!B32:B133,Terméklista!H32:H133)," ") | O15: =IFERROR(ROUNDUP(Rendelés[[#This Row],[Amount/pc]]/_xlfn.XLOOKUP(B15,Terméklista!$B$2:$B$103,Terméklista!$M$2:$M$103,),0)," ") | P15: =IFERROR(ROUNDUP(Rendelés[[#This Row],[Dobozok száma]]/_xlfn.XLOOKUP(B15,Terméklista!$B$2:$B$103,Terméklista!$N$2:$N$103,),0)," ") | Q15: =IFERROR(Rendelés[[#This Row],[Szükséges anyagmennyiség]]+(Rendelés[[#This Row],[Össz raklapok száma]]*25),"") | R15: {=(H15*_xlfn.XLOOKUP(B15,Terméklista!$B$2:$B$103,Terméklista!F$2:$F$103,))/1000} -> 31.5 | S15: =IFERROR(((H15/_xlfn.XLOOKUP(B15,Terméklista!$B$2:$B$103,Terméklista!$E$2:$E$103)*_xlfn.XLOOKUP(B15,Terméklista!$B$2:$B$103,Terméklista!$I$2:$I$103)))/3600," ") -> 126.38889
A16: Seidel Gmbh&co Kg | B16: MA51 | C16: =IFERROR(_xlfn.XLOOKUP(B16,Terméklista!$B$2:$B$103,Terméklista!$C$2:$C$103,)," ") -> Zamak Gewicht | E16: M251012 | F16: =_xlfn.XLOOKUP(B16,Terméklista!$B$2:$B$103,Terméklista!$G$2:$G$103," ") -> Z410 | G16: 4500099914 | H16: 150000 | I16: 2025-01-22 | J16: 2025-03-24 | L16: x | N16: =IFERROR(_xlfn.XLOOKUP(B16,Terméklista!B13:B114,Terméklista!H13:H114)," ") -> 0 | O16: =IFERROR(ROUNDUP(Rendelés[[#This Row],[Amount/pc]]/_xlfn.XLOOKUP(B16,Terméklista!$B$2:$B$103,Terméklista!$M$2:$M$103,),0)," ") -> 429 | P16: =IFERROR(ROUNDUP(Rendelés[[#This Row],[Dobozok száma]]/_xlfn.XLOOKUP(B16,Terméklista!$B$2:$B$103,Terméklista!$N$2:$N$103,),0)," ") -> 15 | Q16: =IFERROR(Rendelés[[#This Row],[Szükséges anyagmennyiség]]+(Rendelés[[#This Row],[Össz raklapok száma]]*25),"") -> 4653 | R16: {=(H16*_xlfn.XLOOKUP(B16,Terméklista!$B$2:$B$103,Terméklista!F$2:$F$103,))/1000} -> 4278 | S16: =IFERROR(((H16/_xlfn.XLOOKUP(B16,Terméklista!$B$2:$B$103,Terméklista!$E$2:$E$103)*_xlfn.XLOOKUP(B16,Terméklista!$B$2:$B$103,Terméklista!$I$2:$I$103)))/3600," ") -> 208.33333 | T16: 2025/23
A17: Ela Solutions Kft. | B17: 90ZA-H001-06 | C17: =IFERROR(_xlfn.XLOOKUP(B17,Terméklista!$B$2:$B$103,Terméklista!$C$2:$C$103,)," ") -> zárház | E17: M251013 | F17: =_xlfn.XLOOKUP(B17,Terméklista!$B$2:$B$103,Terméklista!$G$2:$G$103," ") -> Z410 | G17: 5535 | H17: 1000 | I17: 2025-01-23 | J17: 2025-01-29 | K17: 2025-02-03 | L17: x | N17: =IFERROR(_xlfn.XLOOKUP(B17,Terméklista!B14:B115,Terméklista!H14:H115)," ") -> 0 | O17: =IFERROR(ROUNDUP(Rendelés[[#This Row],[Amount/pc]]/_xlfn.XLOOKUP(B17,Terméklista!$B$2:$B$103,Terméklista!$M$2:$M$103,),0)," ") | P17: =IFERROR(ROUNDUP(Rendelés[[#This Row],[Dobozok száma]]/_xlfn.XLOOKUP(B17,Terméklista!$B$2:$B$103,Terméklista!$N$2:$N$103,),0)," ") | Q17: =IFERROR(Rendelés[[#This Row],[Szükséges anyagmennyiség]]+(Rendelés[[#This Row],[Össz raklapok száma]]*25),"") | R17: {=(H17*_xlfn.XLOOKUP(B17,Terméklista!$B$2:$B$103,Terméklista!F$2:$F$103,))/1000} -> 24.5 | S17: =IFERROR(((H17/_xlfn.XLOOKUP(B17,Terméklista!$B$2:$B$103,Terméklista!$E$2:$E$103)*_xlfn.XLOOKUP(B17,Terméklista!$B$2:$B$103,Terméklista!$I$2:$I$103)))/3600," ") -> 2.0833333
A18: Systec Pos-Technology Gmbh | B18: Verdrehsicherung C3R Flanch | C18: =IFERROR(_xlfn.XLOOKUP(B18,Terméklista!$B$2:$B$103,Terméklista!$C$2:$C$103,)," ") | E18: M251014 | F18: =_xlfn.XLOOKUP(B18,Terméklista!$B$2:$B$103,Terméklista!$G$2:$G$103," ") | G18: 26449 | H18: 5000 | I18: 2025-01-27 | J18: 2025-02-19 | K18: 2025-02-21 | L18: x | N18: =IFERROR(_xlfn.XLOOKUP(B18,Terméklista!B15:B116,Terméklista!H15:H116)," ") | O18: =IFERROR(ROUNDUP(Rendelés[[#This Row],[Amount/pc]]/_xlfn.XLOOKUP(B18,Terméklista!$B$2:$B$103,Terméklista!$M$2:$M$103,),0)," ") | P18: =IFERROR(ROUNDUP(Rendelés[[#This Row],[Dobozok száma]]/_xlfn.XLOOKUP(B18,Terméklista!$B$2:$B$103,Terméklista!$N$2:$N$103,),0)," ") | Q18: =IFERROR(Rendelés[[#This Row],[Szükséges anyagmennyiség]]+(Rendelés[[#This Row],[Össz raklapok száma]]*25),"") | R18: {=(H18*_xlfn.XLOOKUP(B18,Terméklista!$B$2:$B$103,Terméklista!F$2:$F$103,))/1000} -> #N/A | S18: =IFERROR(((H18/_xlfn.XLOOKUP(B18,Terméklista!$B$2:$B$103,Terméklista!$E$2:$E$103)*_xlfn.XLOOKUP(B18,Terméklista!$B$2:$B$103,Terméklista!$I$2:$I$103)))/3600," ")
A19: Systec Pos-Technology Gmbh | B19: Euroloc 2 sperrhacken Zn S | C19: =IFERROR(_xlfn.XLOOKUP(B19,Terméklista!$B$2:$B$103,Terméklista!$C$2:$C$103,)," ") | E19: M251015 | F19: =_xlfn.XLOOKUP(B19,Terméklista!$B$2:$B$103,Terméklista!$G$2:$G$103," ") | G19: 26452 | H19: 20000 | I19: 2025-01-27 | J19: 2025-03-05 | K19: 2025-02-21 | L19: x | N19: =IFERROR(_xlfn.XLOOKUP(B19,Terméklista!B16:B117,Terméklista!H16:H117)," ") | O19: =IFERROR(ROUNDUP(Rendelés[[#This Row],[Amount/pc]]/_xlfn.XLOOKUP(B19,Terméklista!$B$2:$B$103,Terméklista!$M$2:$M$103,),0)," ") | P19: =IFERROR(ROUNDUP(Rendelés[[#This Row],[Dobozok száma]]/_xlfn.XLOOKUP(B19,Terméklista!$B$2:$B$103,Terméklista!$N$2:$N$103,),0)," ") | Q19: =IFERROR(Rendelés[[#This Row],[Szükséges anyagmennyiség]]+(Rendelés[[#This Row],[Össz raklapok száma]]*25),"") | R19: {=(H19*_xlfn.XLOOKUP(B19,Terméklista!$B$2:$B$103,Terméklista!F$2:$F$103,))/1000} -> #N/A | S19: =IFERROR(((H19/_xlfn.XLOOKUP(B19,Terméklista!$B$2:$B$103,Terméklista!$E$2:$E$103)*_xlfn.XLOOKUP(B19,Terméklista!$B$2:$B$103,Terméklista!$I$2:$I$103)))/3600," ") | T19: 2025/22
A20: Seidel Gmbh&co Kg | B20: MB22 | C20: =IFERROR(_xlfn.XLOOKUP(B20,Terméklista!$B$2:$B$103,Terméklista!$C$2:$C$103,)," ") -> Zamak Gewicht | E20: M251016 | F20: =_xlfn.XLOOKUP(B20,Terméklista!$B$2:$B$103,Terméklista!$G$2:$G$103," ") -> Z410 | G20: 4500100205 | H20: 24000 | I20: 2025-02-11 | J20: 2025-03-26 | L20: x | N20: =IFERROR(_xlfn.XLOOKUP(B20,Terméklista!B17:B118,Terméklista!H17:H118)," ") -> 0 | O20: =IFERROR(ROUNDUP(Rendelés[[#This Row],[Amount/pc]]/_xlfn.XLOOKUP(B20,Terméklista!$B$2:$B$103,Terméklista!$M$2:$M$103,),0)," ") -> 24 | P20: =IFERROR(ROUNDUP(Rendelés[[#This Row],[Dobozok száma]]/_xlfn.XLOOKUP(B20,Terméklista!$B$2:$B$103,Terméklista!$N$2:$N$103,),0)," ") -> 1 | Q20: =IFERROR(Rendelés[[#This Row],[Szükséges anyagmennyiség]]+(Rendelés[[#This Row],[Össz raklapok száma]]*25),"") -> 217 | R20: {=(H20*_xlfn.XLOOKUP(B20,Terméklista!$B$2:$B$103,Terméklista!F$2:$F$103,))/1000} -> 192 | S20: =IFERROR(((H20/_xlfn.XLOOKUP(B20,Terméklista!$B$2:$B$103,Terméklista!$E$2:$E$103)*_xlfn.XLOOKUP(B20,Terméklista!$B$2:$B$103,Terméklista!$I$2:$I$103)))/3600," ") -> 8.3333333 | T20: 2025/23
A21: Systec Pos-Technology Gmbh | B21: Smartstop-2 Sperritzteil-2 | C21: =IFERROR(_xlfn.XLOOKUP(B21,Terméklista!$B$2:$B$103,Terméklista!$C$2:$C$103,)," ") | E21: M251019 | F21: =_xlfn.XLOOKUP(B21,Terméklista!$B$2:$B$103,Terméklista!$G$2:$G$103," ") | G21: 26514 | H21: 10000 | I21: 2025-02-12 | J21: 2025-03-27 | L21: x | N21: =IFERROR(_xlfn.XLOOKUP(B21,Terméklista!B20:B121,Terméklista!H20:H121)," ") | O21: =IFERROR(ROUNDUP(Rendelés[[#This Row],[Amount/pc]]/_xlfn.XLOOKUP(B21,Terméklista!$B$2:$B$103,Terméklista!$M$2:$M$103,),0)," ") | P21: =IFERROR(ROUNDUP(Rendelés[[#This Row],[Dobozok száma]]/_xlfn.XLOOKUP(B21,Terméklista!$B$2:$B$103,Terméklista!$N$2:$N$103,),0)," ") | Q21: =IFERROR(Rendelés[[#This Row],[Szükséges anyagmennyiség]]+(Rendelés[[#This Row],[Össz raklapok száma]]*25),"") | R21: {=(H21*_xlfn.XLOOKUP(B21,Terméklista!$B$2:$B$103,Terméklista!F$2:$F$103,))/1000} -> #N/A | S21: =IFERROR(((H21/_xlfn.XLOOKUP(B21,Terméklista!$B$2:$B$103,Terméklista!$E$2:$E$103)*_xlfn.XLOOKUP(B21,Terméklista!$B$2:$B$103,Terméklista!$I$2:$I$103)))/3600," ") | T21: 2025/22
A22: Ela Solutions Kft. | B22: 90ZA-ZS004-00 | C22: =IFERROR(_xlfn.XLOOKUP(B22,Terméklista!$B$2:$B$103,Terméklista!$C$2:$C$103,)," ") -> zsanértest | E22: M251018 | F22: =_xlfn.XLOOKUP(B22,Terméklista!$B$2:$B$103,Terméklista!$G$2:$G$103," ") -> Z410 | G22: 5577 | H22: 200 | I22: 2025-02-13 | J22: 2025-02-20 | K22: 2025-02-21 | L22: x | N22: =IFERROR(_xlfn.XLOOKUP(B22,Terméklista!B19:B120,Terméklista!H19:H120)," ") -> 0 | O22: =IFERROR(ROUNDUP(Rendelés[[#This Row],[Amount/pc]]/_xlfn.XLOOKUP(B22,Terméklista!$B$2:$B$103,Terméklista!$M$2:$M$103,),0)," ") | P22: =IFERROR(ROUNDUP(Rendelés[[#This Row],[Dobozok száma]]/_xlfn.XLOOKUP(B22,Terméklista!$B$2:$B$103,Terméklista!$N$2:$N$103,),0)," ") | Q22: =IFERROR(Rendelés[[#This Row],[Szükséges anyagmennyiség]]+(Rendelés[[#This Row],[Össz raklapok száma]]*25),"") | R22: {=(H22*_xlfn.XLOOKUP(B22,Terméklista!$B$2:$B$103,Terméklista!F$2:$F$103,))/1000} -> 14 | S22: =IFERROR(((H22/_xlfn.XLOOKUP(B22,Terméklista!$B$2:$B$103,Terméklista!$E$2:$E$103)*_xlfn.XLOOKUP(B22,Terméklista!$B$2:$B$103,Terméklista!$I$2:$I$103)))/3600," ") -> 0.41666667
A23: Seidel Gmbh&co Kg | B23: MA41 | C23: =IFERROR(_xlfn.XLOOKUP(B23,Terméklista!$B$2:$B$103,Terméklista!$C$2:$C$103,)," ") -> Zamak Gewicht | E23: M251020 | F23: =_xlfn.XLOOKUP(B23,Terméklista!$B$2:$B$103,Terméklista!$G$2:$G$103," ") -> Z410 | G23: 4500100294 | H23: 50000 | I23: 2025-02-17 | J23: 2025-05-26 | K23: 2025-05-14 | L23: x | N23: =IFERROR(_xlfn.XLOOKUP(B23,Terméklista!B21:B122,Terméklista!H21:H122)," ") -> 0 | O23: =IFERROR(ROUNDUP(Rendelés[[#This Row],[Amount/pc]]/_xlfn.XLOOKUP(B23,Terméklista!$B$2:$B$103,Terméklista!$M$2:$M$103,),0)," ") -> 143 | P23: =IFERROR(ROUNDUP(Rendelés[[#This Row],[Dobozok száma]]/_xlfn.XLOOKUP(B23,Terméklista!$B$2:$B$103,Terméklista!$N$2:$N$103,),0)," ") -> 2 | Q23: =IFERROR(Rendelés[[#This Row],[Szükséges anyagmennyiség]]+(Rendelés[[#This Row],[Össz raklapok száma]]*25),"") -> 900 | R23: {=(H23*_xlfn.XLOOKUP(B23,Terméklista!$B$2:$B$103,Terméklista!F$2:$F$103,))/1000} -> 850 | S23: =IFERROR(((H23/_xlfn.XLOOKUP(B23,Terméklista!$B$2:$B$103,Terméklista!$E$2:$E$103)*_xlfn.XLOOKUP(B23,Terméklista!$B$2:$B$103,Terméklista!$I$2:$I$103)))/3600," ") -> 34.722222 | T23: 2025/27
A24: Fasten Italia S.R.L | B24: P6 body | C24: =IFERROR(_xlfn.XLOOKUP(B24,Terméklista!$B$2:$B$103,Terméklista!$C$2:$C$103,)," ") -> 0 | E24: M251021 | F24: =_xlfn.XLOOKUP(B24,Terméklista!$B$2:$B$103,Terméklista!$G$2:$G$103," ") -> Z410 | G24: 25/00113 | H24: 30000 | I24: 2025-02-17 | J24: 2025-04-16 | L24: x | M24: CMR | N24: =IFERROR(_xlfn.XLOOKUP(B24,Terméklista!B22:B123,Terméklista!H22:H123)," ") -> 0 | O24: =IFERROR(ROUNDUP(Rendelés[[#This Row],[Amount/pc]]/_xlfn.XLOOKUP(B24,Terméklista!$B$2:$B$103,Terméklista!$M$2:$M$103,),0)," ") | P24: =IFERROR(ROUNDUP(Rendelés[[#This Row],[Dobozok száma]]/_xlfn.XLOOKUP(B24,Terméklista!$B$2:$B$103,Terméklista!$N$2:$N$103,),0)," ") | Q24: =IFERROR(Rendelés[[#This Row],[Szükséges anyagmennyiség]]+(Rendelés[[#This Row],[Össz raklapok száma]]*25),"") | R24: {=(H24*_xlfn.XLOOKUP(B24,Terméklista!$B$2:$B$103,Terméklista!F$2:$F$103,))/1000} -> 0 | S24: =IFERROR(((H24/_xlfn.XLOOKUP(B24,Terméklista!$B$2:$B$103,Terméklista!$E$2:$E$103)*_xlfn.XLOOKUP(B24,Terméklista!$B$2:$B$103,Terméklista!$I$2:$I$103)))/3600," ") | T24: 2025/34
A25: Fasten Italia S.R.L | B25: YKK fogó | C25: =IFERROR(_xlfn.XLOOKUP(B25,Terméklista!$B$2:$B$103,Terméklista!$C$2:$C$103,)," ") -> 0 | E25: M251022 | F25: =_xlfn.XLOOKUP(B25,Terméklista!$B$2:$B$103,Terméklista!$G$2:$G$103," ") -> Z410 | G25: 25/00113 | H25: 30000 | I25: 2025-02-17 | J25: 2025-04-16 | L25: x | M25: CMR | N25: =IFERROR(_xlfn.XLOOKUP(B25,Terméklista!B23:B124,Terméklista!H23:H124)," ") -> 0 | O25: =IFERROR(ROUNDUP(Rendelés[[#This Row],[Amount/pc]]/_xlfn.XLOOKUP(B25,Terméklista!$B$2:$B$103,Terméklista!$M$2:$M$103,),0)," ") | P25: =IFERROR(ROUNDUP(Rendelés[[#This Row],[Dobozok száma]]/_xlfn.XLOOKUP(B25,Terméklista!$B$2:$B$103,Terméklista!$N$2:$N$103,),0)," ") | Q25: =IFERROR(Rendelés[[#This Row],[Szükséges anyagmennyiség]]+(Rendelés[[#This Row],[Össz raklapok száma]]*25),"") | R25: {=(H25*_xlfn.XLOOKUP(B25,Terméklista!$B$2:$B$103,Terméklista!F$2:$F$103,))/1000} -> 0 | S25: =IFERROR(((H25/_xlfn.XLOOKUP(B25,Terméklista!$B$2:$B$103,Terméklista!$E$2:$E$103)*_xlfn.XLOOKUP(B25,Terméklista!$B$2:$B$103,Terméklista!$I$2:$I$103)))/3600," ") | T25: 2025/34
A26: Ela Solutions Kft. | B26: 90ZA-B0011-06 | C26: =IFERROR(_xlfn.XLOOKUP(B26,Terméklista!$B$2:$B$103,Terméklista!$C$2:$C$103,)," ") -> 0 | E26: M251023 | F26: =_xlfn.XLOOKUP(B26,Terméklista!$B$2:$B$103,Terméklista!$G$2:$G$103," ") -> Z410 | G26: 5585 | H26: 992 | I26: 2025-02-21 | J26: 2025-02-26 | K26: 2025-02-26 | L26: x | N26: =IFERROR(_xlfn.XLOOKUP(B26,Terméklista!B24:B125,Terméklista!H24:H125)," ") -> 0 | O26: =IFERROR(ROUNDUP(Rendelés[[#This Row],[Amount/pc]]/_xlfn.XLOOKUP(B26,Terméklista!$B$2:$B$103,Terméklista!$M$2:$M$103,),0)," ") | P26: =IFERROR(ROUNDUP(Rendelés[[#This Row],[Dobozok száma]]/_xlfn.XLOOKUP(B26,Terméklista!$B$2:$B$103,Terméklista!$N$2:$N$103,),0)," ") | Q26: =IFERROR(Rendelés[[#This Row],[Szükséges anyagmennyiség]]+(Rendelés[[#This Row],[Össz raklapok száma]]*25),"") | R26: {=(H26*_xlfn.XLOOKUP(B26,Terméklista!$B$2:$B$103,Terméklista!F$2:$F$103,))/1000} -> 2.86688 | S26: =IFERROR(((H26/_xlfn.XLOOKUP(B26,Terméklista!$B$2:$B$103,Terméklista!$E$2:$E$103)*_xlfn.XLOOKUP(B26,Terméklista!$B$2:$B$103,Terméklista!$I$2:$I$103)))/3600," ")
A27: Seidel Gmbh&co Kg | B27: MA51 | C27: =IFERROR(_xlfn.XLOOKUP(B27,Terméklista!$B$2:$B$103,Terméklista!$C$2:$C$103,)," ") -> Zamak Gewicht | E27: M251024 | F27: =_xlfn.XLOOKUP(B27,Terméklista!$B$2:$B$103,Terméklista!$G$2:$G$103," ") -> Z410 | G27: 4500100427 | H27: 50000 | I27: 2025-02-25 | J27: 2025-04-17 | K27: 2025-04-10 | L27: x | N27: =IFERROR(_xlfn.XLOOKUP(B27,Terméklista!B25:B126,Terméklista!H25:H126)," ") -> 0 | O27: =IFERROR(ROUNDUP(Rendelés[[#This Row],[Amount/pc]]/_xlfn.XLOOKUP(B27,Terméklista!$B$2:$B$103,Terméklista!$M$2:$M$103,),0)," ") -> 143 | P27: =IFERROR(ROUNDUP(Rendelés[[#This Row],[Dobozok száma]]/_xlfn.XLOOKUP(B27,Terméklista!$B$2:$B$103,Terméklista!$N$2:$N$103,),0)," ") -> 5 | Q27: =IFERROR(Rendelés[[#This Row],[Szükséges anyagmennyiség]]+(Rendelés[[#This Row],[Össz raklapok száma]]*25),"") -> 1551 | R27: {=(H27*_xlfn.XLOOKUP(B27,Terméklista!$B$2:$B$103,Terméklista!F$2:$F$103,))/1000} -> 1426 | S27: =IFERROR(((H27/_xlfn.XLOOKUP(B27,Terméklista!$B$2:$B$103,Terméklista!$E$2:$E$103)*_xlfn.XLOOKUP(B27,Terméklista!$B$2:$B$103,Terméklista!$I$2:$I$103)))/3600," ") -> 69.444444 | T27: 2025/30
A28: Systec Pos-Technology Gmbh | B28: Rasthebel-2 | C28: =IFERROR(_xlfn.XLOOKUP(B28,Terméklista!$B$2:$B$103,Terméklista!$C$2:$C$103,)," ") -> Smartstop-2 | E28: M251026 | F28: =_xlfn.XLOOKUP(B28,Terméklista!$B$2:$B$103,Terméklista!$G$2:$G$103," ") -> Z410 | G28: 26594 | H28: 10000 | I28: 2025-03-03 | J28: 2025-04-02 | K28: 2025-04-15 | L28: x | M28: CMR | N28: =IFERROR(_xlfn.XLOOKUP(B28,Terméklista!B27:B128,Terméklista!H27:H128)," ") -> 0 | O28: =IFERROR(ROUNDUP(Rendelés[[#This Row],[Amount/pc]]/_xlfn.XLOOKUP(B28,Terméklista!$B$2:$B$103,Terméklista!$M$2:$M$103,),0)," ") -> 16 | P28: =IFERROR(ROUNDUP(Rendelés[[#This Row],[Dobozok száma]]/_xlfn.XLOOKUP(B28,Terméklista!$B$2:$B$103,Terméklista!$N$2:$N$103,),0)," ") -> 1 | Q28: =IFERROR(Rendelés[[#This Row],[Szükséges anyagmennyiség]]+(Rendelés[[#This Row],[Össz raklapok száma]]*25),"") -> 175.3 | R28: {=(H28*_xlfn.XLOOKUP(B28,Terméklista!$B$2:$B$103,Terméklista!F$2:$F$103,))/1000} -> 150.3 | S28: =IFERROR(((H28/_xlfn.XLOOKUP(B28,Terméklista!$B$2:$B$103,Terméklista!$E$2:$E$103)*_xlfn.XLOOKUP(B28,Terméklista!$B$2:$B$103,Terméklista!$I$2:$I$103)))/3600," ") -> 6.9444444 | T28: 2025/34
A29: Seidel Gmbh&co Kg | B29: MA41 | C29: =IFERROR(_xlfn.XLOOKUP(B29,Terméklista!$B$2:$B$103,Terméklista!$C$2:$C$103,)," ") -> Zamak Gewicht | E29: M251025 | F29: =_xlfn.XLOOKUP(B29,Terméklista!$B$2:$B$103,Terméklista!$G$2:$G$103," ") -> Z410 | G29: 4500100560 | H29: 50000 | I29: 2025-03-04 | J29: 2025-06-02 | K29: 2025-06-05 | L29: x | N29: =_xlfn.XLOOKUP(J29,Terméklista!$B$2:$B$103,Terméklista!$H$2:$H$103," ") | O29: =IFERROR(ROUNDUP(Rendelés[[#This Row],[Amount/pc]]/_xlfn.XLOOKUP(B29,Terméklista!$B$2:$B$103,Terméklista!$M$2:$M$103,),0)," ") -> 143 | P29: =IFERROR(ROUNDUP(Rendelés[[#This Row],[Dobozok száma]]/_xlfn.XLOOKUP(B29,Terméklista!$B$2:$B$103,Terméklista!$N$2:$N$103,),0)," ") -> 2 | Q29: =IFERROR(Rendelés[[#This Row],[Szükséges anyagmennyiség]]+(Rendelés[[#This Row],[Össz raklapok száma]]*25),"") -> 900 | R29: {=(H29*_xlfn.XLOOKUP(B29,Terméklista!$B$2:$B$103,Terméklista!F$2:$F$103,))/1000} -> 850 | S29: =IFERROR(((H29/_xlfn.XLOOKUP(B29,Terméklista!$B$2:$B$103,Terméklista!$E$2:$E$103)*_xlfn.XLOOKUP(B29,Terméklista!$B$2:$B$103,Terméklista!$I$2:$I$103)))/3600," ") -> 34.722222
A30: Systec Pos-Technology Gmbh | B30: CVLROH | C30: =IFERROR(_xlfn.XLOOKUP(B30,Terméklista!$B$2:$B$103,Terméklista!$C$2:$C$103,)," ") -> Verdrehsicherung | E30: M251028 | F30: =_xlfn.XLOOKUP(B30,Terméklista!$B$2:$B$103,Terméklista!$G$2:$G$103," ") -> Z410 | G30: 26607 | H30: 5000 | I30: 2025-03-06 | J30: 2025-04-18 | K30: 2025-04-08 | L30: x | M30: CMR | N30: =IFERROR(_xlfn.XLOOKUP(B30,Terméklista!B29:B130,Terméklista!H29:H130)," ") -> 0 | O30: =IFERROR(ROUNDUP(Rendelés[[#This Row],[Amount/pc]]/_xlfn.XLOOKUP(B30,Terméklista!$B$2:$B$103,Terméklista!$M$2:$M$103,),0)," ") -> 25 | P30: =IFERROR(ROUNDUP(Rendelés[[#This Row],[Dobozok száma]]/_xlfn.XLOOKUP(B30,Terméklista!$B$2:$B$103,Terméklista!$N$2:$N$103,),0)," ") -> 1 | Q30: =IFERROR(Rendelés[[#This Row],[Szükséges anyagmennyiség]]+(Rendelés[[#This Row],[Össz raklapok száma]]*25),"") -> 298.5 | R30: {=(H30*_xlfn.XLOOKUP(B30,Terméklista!$B$2:$B$103,Terméklista!F$2:$F$103,))/1000} -> 273.5 | S30: =IFERROR(((H30/_xlfn.XLOOKUP(B30,Terméklista!$B$2:$B$103,Terméklista!$E$2:$E$103)*_xlfn.XLOOKUP(B30,Terméklista!$B$2:$B$103,Terméklista!$I$2:$I$103)))/3600," ") -> 10.416667 | T30: 2025/34
A31: Ela Solutions Kft. | B31: 90ZA-ZK001-06 | C31: =IFERROR(_xlfn.XLOOKUP(B31,Terméklista!$B$2:$B$103,Terméklista!$C$2:$C$103,)," ") -> 0 | E31: M251027 | F31: =_xlfn.XLOOKUP(B31,Terméklista!$B$2:$B$103,Terméklista!$G$2:$G$103," ") -> Z410 | G31: 5611 | H31: 2000 | I31: 2025-03-06 | J31: 2025-03-10 | K31: 2025-03-10 | L31: x | N31: =IFERROR(_xlfn.XLOOKUP(B31,Terméklista!B28:B129,Terméklista!H28:H129)," ") | O31: =IFERROR(ROUNDUP(Rendelés[[#This Row],[Amount/pc]]/_xlfn.XLOOKUP(B31,Terméklista!$B$2:$B$103,Terméklista!$M$2:$M$103,),0)," ") | P31: =IFERROR(ROUNDUP(Rendelés[[#This Row],[Dobozok száma]]/_xlfn.XLOOKUP(B31,Terméklista!$B$2:$B$103,Terméklista!$N$2:$N$103,),0)," ") | Q31: =IFERROR(Rendelés[[#This Row],[Szükséges anyagmennyiség]]+(Rendelés[[#This Row],[Össz raklapok száma]]*25),"") | R31: {=(H31*_xlfn.XLOOKUP(B31,Terméklista!$B$2:$B$103,Terméklista!F$2:$F$103,))/1000} -> 44.68 | S31: =IFERROR(((H31/_xlfn.XLOOKUP(B31,Terméklista!$B$2:$B$103,Terméklista!$E$2:$E$103)*_xlfn.XLOOKUP(B31,Terméklista!$B$2:$B$103,Terméklista!$I$2:$I$103)))/3600," ") -> 4.1666667
A32: Seidel Gmbh&co Kg | B32: MA66 | C32: =IFERROR(_xlfn.XLOOKUP(B32,Terméklista!$B$2:$B$103,Terméklista!$C$2:$C$103,)," ") -> Zamak Gewicht | E32: M251029 | F32: =_xlfn.XLOOKUP(B32,Terméklista!$B$2:$B$103,Terméklista!$G$2:$G$103," ") -> Z410 | G32: 4500100603 | H32: 300000 | I32: 2025-03-06 | J32: 2025-05-15 | K32: 2025-05-14 | L32: x | N32: =IFERROR(_xlfn.XLOOKUP(B32,Terméklista!B30:B131,Terméklista!H30:H131)," ") -> 0 | O32: =IFERROR(ROUNDUP(Rendelés[[#This Row],[Amount/pc]]/_xlfn.XLOOKUP(B32,Terméklista!$B$2:$B$103,Terméklista!$M$2:$M$103,),0)," ") -> 600 | P32: =IFERROR(ROUNDUP(Rendelés[[#This Row],[Dobozok száma]]/_xlfn.XLOOKUP(B32,Terméklista!$B$2:$B$103,Terméklista!$N$2:$N$103,),0)," ") -> 7 | Q32: =IFERROR(Rendelés[[#This Row],[Szükséges anyagmennyiség]]+(Rendelés[[#This Row],[Össz raklapok száma]]*25),"") -> 3325 | R32: {=(H32*_xlfn.XLOOKUP(B32,Terméklista!$B$2:$B$103,Terméklista!F$2:$F$103,))/1000} -> 3150 | S32: =IFERROR(((H32/_xlfn.XLOOKUP(B32,Terméklista!$B$2:$B$103,Terméklista!$E$2:$E$103)*_xlfn.XLOOKUP(B32,Terméklista!$B$2:$B$103,Terméklista!$I$2:$I$103)))/3600," ") -> 208.33333 | T32: 2025/27
A33: Seidel Gmbh&co Kg | B33: MA66 | C33: =IFERROR(_xlfn.XLOOKUP(B33,Terméklista!$B$2:$B$103,Terméklista!$C$2:$C$103,)," ") -> Zamak Gewicht | E33: M251030 | F33: =_xlfn.XLOOKUP(B33,Terméklista!$B$2:$B$103,Terméklista!$G$2:$G$103," ") -> Z410 | G33: 4500100603 | H33: 200000 | I33: 2025-03-06 | J33: 2025-06-25 | K33: 2025-06-19 | L33: x | N33: =_xlfn.XLOOKUP(J33,Terméklista!$B$2:$B$103,Terméklista!$H$2:$H$103," ") | O33: =IFERROR(ROUNDUP(Rendelés[[#This Row],[Amount/pc]]/_xlfn.XLOOKUP(B33,Terméklista!$B$2:$B$103,Terméklista!$M$2:$M$103,),0)," ") -> 400 | P33: =IFERROR(ROUNDUP(Rendelés[[#This Row],[Dobozok száma]]/_xlfn.XLOOKUP(B33,Terméklista!$B$2:$B$103,Terméklista!$N$2:$N$103,),0)," ") -> 5 | Q33: =IFERROR(Rendelés[[#This Row],[Szükséges anyagmennyiség]]+(Rendelés[[#This Row],[Össz raklapok száma]]*25),"") -> 2225 | R33: {=(H33*_xlfn.XLOOKUP(B33,Terméklista!$B$2:$B$103,Terméklista!F$2:$F$103,))/1000} -> 2100 | S33: =IFERROR(((H33/_xlfn.XLOOKUP(B33,Terméklista!$B$2:$B$103,Terméklista!$E$2:$E$103)*_xlfn.XLOOKUP(B33,Terméklista!$B$2:$B$103,Terméklista!$I$2:$I$103)))/3600," ") -> 138.88889
A34: Seidel Gmbh&co Kg | B34: MB22 | E34: M251048 | F34: =_xlfn.XLOOKUP(B34,Terméklista!$B$2:$B$103,Terméklista!$G$2:$G$103," ") -> Z410 | G34: 4500100868 | H34: 92000 | I34: 2025-03-06 | J34: 2025-06-18 | K34: 2025-06-13 | L34: x | M34: CMR | N34: =_xlfn.XLOOKUP(J34,Terméklista!$B$2:$B$103,Terméklista!$H$2:$H$103," ") | O34: =IFERROR(ROUNDUP(Rendelés[[#This Row],[Amount/pc]]/_xlfn.XLOOKUP(B34,Terméklista!$B$2:$B$103,Terméklista!$M$2:$M$103,),0)," ") -> 92 | P34: =IFERROR(ROUNDUP(Rendelés[[#This Row],[Dobozok száma]]/_xlfn.XLOOKUP(B34,Terméklista!$B$2:$B$103,Terméklista!$N$2:$N$103,),0)," ") -> 1 | Q34: =IFERROR(Rendelés[[#This Row],[Szükséges anyagmennyiség]]+(Rendelés[[#This Row],[Össz raklapok száma]]*25),"") -> 761 | R34: {=(H34*_xlfn.XLOOKUP(B34,Terméklista!$B$2:$B$103,Terméklista!F$2:$F$103,))/1000} -> 736 | S34: =IFERROR(((H34/_xlfn.XLOOKUP(B34,Terméklista!$B$2:$B$103,Terméklista!$E$2:$E$103)*_xlfn.XLOOKUP(B34,Terméklista!$B$2:$B$103,Terméklista!$I$2:$I$103)))/3600," ") -> 31.944444 | T34: 2025/44
A35: Arsisco AMO Pack LLC | B35: Töltő sin | C35: 0 | E35: M251032 | F35: =_xlfn.XLOOKUP(B35,Terméklista!$B$2:$B$103,Terméklista!$G$2:$G$103," ") -> Z414 | H35: 1000 | I35: 2025-03-14 | J35: 2025-03-31 | K35: 2025-04-03 | L35: x | N35: =IFERROR(_xlfn.XLOOKUP(B35,Terméklista!B33:B134,Terméklista!H33:H134)," ") | O35: =IFERROR(ROUNDUP(Rendelés[[#This Row],[Amount/pc]]/_xlfn.XLOOKUP(B35,Terméklista!$B$2:$B$103,Terméklista!$M$2:$M$103,),0)," ") | P35: =IFERROR(ROUNDUP(Rendelés[[#This Row],[Dobozok száma]]/_xlfn.XLOOKUP(B35,Terméklista!$B$2:$B$103,Terméklista!$N$2:$N$103,),0)," ") | Q35: =IFERROR(Rendelés[[#This Row],[Szükséges anyagmennyiség]]+(Rendelés[[#This Row],[Össz raklapok száma]]*25),"") | R35: {=(H35*_xlfn.XLOOKUP(B35,Terméklista!$B$2:$B$103,Terméklista!F$2:$F$103,))/1000} -> 0 | S35: =IFERROR(((H35/_xlfn.XLOOKUP(B35,Terméklista!$B$2:$B$103,Terméklista!$E$2:$E$103)*_xlfn.XLOOKUP(B35,Terméklista!$B$2:$B$103,Terméklista!$I$2:$I$103)))/3600," ")
A36: Seidel Gmbh&co Kg | B36: M83 | C36: =IFERROR(_xlfn.XLOOKUP(B36,Terméklista!$B$2:$B$103,Terméklista!$C$2:$C$103,)," ") -> Zamak Gewicht | E36: M251038 | F36: =_xlfn.XLOOKUP(B36,Terméklista!$B$2:$B$103,Terméklista!$G$2:$G$103," ") -> Z410 | G36: 4500100908 | H36: 90000 | I36: 2025-03-25 | J36: 2025-06-02 | K36: 2025-06-05 | L36: x | N36: =_xlfn.XLOOKUP(J36,Terméklista!$B$2:$B$103,Terméklista!$H$2:$H$103," ") | O36: =IFERROR(ROUNDUP(Rendelés[[#This Row],[Amount/pc]]/_xlfn.XLOOKUP(B36,Terméklista!$B$2:$B$103,Terméklista!$M$2:$M$103,),0)," ") -> 600 | P36: =IFERROR(ROUNDUP(Rendelés[[#This Row],[Dobozok száma]]/_xlfn.XLOOKUP(B36,Terméklista!$B$2:$B$103,Terméklista!$N$2:$N$103,),0)," ") -> 20 | Q36: =IFERROR(Rendelés[[#This Row],[Szükséges anyagmennyiség]]+(Rendelés[[#This Row],[Össz raklapok száma]]*25),"") -> 6377 | R36: {=(H36*_xlfn.XLOOKUP(B36,Terméklista!$B$2:$B$103,Terméklista!F$2:$F$103,))/1000} -> 5877 | S36: =IFERROR(((H36/_xlfn.XLOOKUP(B36,Terméklista!$B$2:$B$103,Terméklista!$E$2:$E$103)*_xlfn.XLOOKUP(B36,Terméklista!$B$2:$B$103,Terméklista!$I$2:$I$103)))/3600," ") -> 125
A37: Ela Solutions Kft. | B37: 90ZA-ZS004-00 | C37: =IFERROR(_xlfn.XLOOKUP(B37,Terméklista!$B$2:$B$103,Terméklista!$C$2:$C$103,)," ") -> zsanértest | E37: M251033 | F37: =_xlfn.XLOOKUP(B37,Terméklista!$B$2:$B$103,Terméklista!$G$2:$G$103," ") -> Z410 | G37: 5664 | H37: 550 | I37: 2025-04-02 | J37: 2025-04-04 | K37: 2025-04-07 | L37: x | N37: =IFERROR(_xlfn.XLOOKUP(B37,Terméklista!B34:B135,Terméklista!H34:H135)," ") -> 0 | O37: =IFERROR(ROUNDUP(Rendelés[[#This Row],[Amount/pc]]/_xlfn.XLOOKUP(B37,Terméklista!$B$2:$B$103,Terméklista!$M$2:$M$103,),0)," ") | P37: =IFERROR(ROUNDUP(Rendelés[[#This Row],[Dobozok száma]]/_xlfn.XLOOKUP(B37,Terméklista!$B$2:$B$103,Terméklista!$N$2:$N$103,),0)," ") | Q37: =IFERROR(Rendelés[[#This Row],[Szükséges anyagmennyiség]]+(Rendelés[[#This Row],[Össz raklapok száma]]*25),"") | R37: {=(H37*_xlfn.XLOOKUP(B37,Terméklista!$B$2:$B$103,Terméklista!F$2:$F$103,))/1000} -> 38.5 | S37: =IFERROR(((H37/_xlfn.XLOOKUP(B37,Terméklista!$B$2:$B$103,Terméklista!$E$2:$E$103)*_xlfn.XLOOKUP(B37,Terméklista!$B$2:$B$103,Terméklista!$I$2:$I$103)))/3600," ") -> 1.1458333
A38: Ela Solutions Kft. | B38: 90ZA-ZK011-06 | C38: =IFERROR(_xlfn.XLOOKUP(B38,Terméklista!$B$2:$B$103,Terméklista!$C$2:$C$103,)," ") -> nagykulcs - 3mm | E38: M251035 | F38: =_xlfn.XLOOKUP(B38,Terméklista!$B$2:$B$103,Terméklista!$G$2:$G$103," ") -> Z410 | G38: 5681 | H38: 1000 | I38: 2025-04-14 | J38: 2025-05-05 | L38: x | N38: =IFERROR(_xlfn.XLOOKUP(B38,Terméklista!B36:B137,Terméklista!H36:H137)," ") | O38: =IFERROR(ROUNDUP(Rendelés[[#This Row],[Amount/pc]]/_xlfn.XLOOKUP(B38,Terméklista!$B$2:$B$103,Terméklista!$M$2:$M$103,),0)," ") | P38: =IFERROR(ROUNDUP(Rendelés[[#This Row],[Dobozok száma]]/_xlfn.XLOOKUP(B38,Terméklista!$B$2:$B$103,Terméklista!$N$2:$N$103,),0)," ") | Q38: =IFERROR(Rendelés[[#This Row],[Szükséges anyagmennyiség]]+(Rendelés[[#This Row],[Össz raklapok száma]]*25),"") | R38: {=(H38*_xlfn.XLOOKUP(B38,Terméklista!$B$2:$B$103,Terméklista!F$2:$F$103,))/1000} -> 47.55 | S38: =IFERROR(((H38/_xlfn.XLOOKUP(B38,Terméklista!$B$2:$B$103,Terméklista!$E$2:$E$103)*_xlfn.XLOOKUP(B38,Terméklista!$B$2:$B$103,Terméklista!$I$2:$I$103)))/3600," ") -> 2.0833333 | T38: 2025/39
A39: Seidel Gmbh&co Kg | B39: MA41 | C39: =IFERROR(_xlfn.XLOOKUP(B39,Terméklista!$B$2:$B$103,Terméklista!$C$2:$C$103,)," ") -> Zamak Gewicht | E39: M251039 | F39: =_xlfn.XLOOKUP(B39,Terméklista!$B$2:$B$103,Terméklista!$G$2:$G$103," ") -> Z410 | G39: 4500101272 | H39: 50000 | I39: 2025-04-23 | J39: 2025-08-04 | K39: 2025-08-05 | L39: x | M39: CMR | N39: =_xlfn.XLOOKUP(J39,Terméklista!$B$2:$B$103,Terméklista!$H$2:$H$103," ") | O39: =IFERROR(ROUNDUP(Rendelés[[#This Row],[Amount/pc]]/_xlfn.XLOOKUP(B39,Terméklista!$B$2:$B$103,Terméklista!$M$2:$M$103,),0)," ") -> 143 | P39: =IFERROR(ROUNDUP(Rendelés[[#This Row],[Dobozok száma]]/_xlfn.XLOOKUP(B39,Terméklista!$B$2:$B$103,Terméklista!$N$2:$N$103,),0)," ") -> 2 | Q39: =IFERROR(Rendelés[[#This Row],[Szükséges anyagmennyiség]]+(Rendelés[[#This Row],[Össz raklapok száma]]*25),"") -> 900 | R39: {=(H39*_xlfn.XLOOKUP(B39,Terméklista!$B$2:$B$103,Terméklista!F$2:$F$103,))/1000} -> 850 | S39: =IFERROR(((H39/_xlfn.XLOOKUP(B39,Terméklista!$B$2:$B$103,Terméklista!$E$2:$E$103)*_xlfn.XLOOKUP(B39,Terméklista!$B$2:$B$103,Terméklista!$I$2:$I$103)))/3600," ") -> 34.722222 | T39: 2025/56
A40: Ela Solutions Kft. | B40: 90ZA-H021-06 | C40: =IFERROR(_xlfn.XLOOKUP(B40,Terméklista!$B$2:$B$103,Terméklista!$C$2:$C$103,)," ") -> lakattal zárható zárház | E40: M251040 | F40: =_xlfn.XLOOKUP(B40,Terméklista!$B$2:$B$103,Terméklista!$G$2:$G$103," ") -> Z410 | G40: 5696 | H40: 200 | I40: 2025-04-25 | J40: 2025-04-28 | L40: x | N40: =IFERROR(_xlfn.XLOOKUP(B40,Terméklista!B41:B142,Terméklista!H41:H142)," ") | O40: =IFERROR(ROUNDUP(Rendelés[[#This Row],[Amount/pc]]/_xlfn.XLOOKUP(B40,Terméklista!$B$2:$B$103,Terméklista!$M$2:$M$103,),0)," ") | P40: =IFERROR(ROUNDUP(Rendelés[[#This Row],[Dobozok száma]]/_xlfn.XLOOKUP(B40,Terméklista!$B$2:$B$103,Terméklista!$N$2:$N$103,),0)," ") | Q40: =IFERROR(Rendelés[[#This Row],[Szükséges anyagmennyiség]]+(Rendelés[[#This Row],[Össz raklapok száma]]*25),"") | R40: {=(H40*_xlfn.XLOOKUP(B40,Terméklista!$B$2:$B$103,Terméklista!F$2:$F$103,))/1000} -> 18.512 | S40: =IFERROR(((H40/_xlfn.XLOOKUP(B40,Terméklista!$B$2:$B$103,Terméklista!$E$2:$E$103)*_xlfn.XLOOKUP(B40,Terméklista!$B$2:$B$103,Terméklista!$I$2:$I$103)))/3600," ") -> 0.41666667 | T40: 2025/39
...

Sheet Gyártás-Csomagolás
A1: Megrendelési információ | J1: Lila | K1: 11 | M1: =SUM(M3:M762) -> 0 | Y1: 25
A2: Customer | B2: Termék neve | C2: Megnevezése | D2: Megjegyzés | E2: Saját rendelési szám | F2: Anyag | G2: Mennyiség | H2: Required delivery date (year/month/day) | I2: Felületkezelés | J2: Szállításra kész | K2: Össz dobozok száma db | L2: Össz raklapok száma | M2: Össz nettó súly | N2: Össz bruttó súly | O2: címke adatok/doboz doboz: termék darab, dátum | P2: milyen utómunka kell pl mosás (M), sorjázás (S), koptatás (K) válogatás (V) kézi tördelés (KT) (felsorolás) | Q2: Utómunka fele kész (x) | R2: Utómunka kész (x) | S2: MEO megtörtént (x) | T2: Selejt % | U2: Mérés & Dobozolás kész (x) | V2: Szállítható (dátum) | W2: Várható késés (x) | X2: Új időpont késés esetén | Y2: rendelési szám
A3: Arsisco AMO Pack LLC | C3: 0 | E3: szerszám - sin5 | H3: 2025-07-16 | I3: =IFERROR(_xlfn.XLOOKUP(B3,Terméklista!$B$6:$B$105,Terméklista!$H$6:$H$105)," ") -> 0 | N3: =IFERROR(M3+(L3*30),"")
A4: Arsisco AMO Pack LLC | C4: 0 | D4: szerszám - sin5 | E4: M251044 | H4: 2025-07-16 | I4: =IFERROR(_xlfn.XLOOKUP(B4,Terméklista!$B$6:$B$105,Terméklista!$H$6:$H$105)," ") -> 0 | N4: =IFERROR(M4+(L4*30),"")
A5: Fasten Italia S.R.L | B5: P6 body | C5: 0 | G5: 11000 | I5: =IFERROR(_xlfn.XLOOKUP(B5,Terméklista!$B$6:$B$105,Terméklista!$H$6:$H$105)," ") -> 0 | N5: =IFERROR(M5+(L5*30),"") -> 0 | Y5: 25/00646
A6: Fasten Italia S.R.L | B6: YKK fogó | C6: 0 | G6: 30000 | I6: =IFERROR(_xlfn.XLOOKUP(B6,Terméklista!$B$6:$B$105,Terméklista!$H$6:$H$105)," ") -> 0 | N6: =IFERROR(M6+(L6*30),"") -> 0 | Y6: 25/00646
A7: Seidel Gmbh&co Kg | B7: MA66 | C7: Zamak Gewicht | D7: POS010 | G7: 200000 | H7: 2026-03-09 | I7: =IFERROR(_xlfn.XLOOKUP(B7,Terméklista!$B$6:$B$105,Terméklista!$H$6:$H$105)," ") -> 0 | N7: =IFERROR(M7+(L7*30),"") -> 0 | Y7: 4500104126
A8: Seidel Gmbh&co Kg | B8: MA66 | C8: Zamak Gewicht | D8: POS010 | G8: 250000 | H8: 2026-03-16 | I8: =IFERROR(_xlfn.XLOOKUP(B8,Terméklista!$B$6:$B$105,Terméklista!$H$6:$H$105)," ") -> 0 | N8: =IFERROR(M8+(L8*30),"") -> 0 | Y8: 4500104215
A9: Seidel Gmbh&co Kg | B9: M83 | C9: Zamak Gewicht | D9: POS010 | G9: 33750 | H9: 2026-02-25 | I9: =IFERROR(_xlfn.XLOOKUP(B9,Terméklista!$B$6:$B$105,Terméklista!$H$6:$H$105)," ") -> 0 | N9: =IFERROR(M9+(L9*30),"") -> 0 | Y9: 4500104347
A10: Seidel Gmbh&co Kg | B10: MA41 | C10: Zamak Gewicht | D10: POS020 | G10: 50000 | H10: 2026-02-25 | I10: =IFERROR(_xlfn.XLOOKUP(B10,Terméklista!$B$6:$B$105,Terméklista!$H$6:$H$105)," ") -> 0 | N10: =IFERROR(M10+(L10*30),"") -> 0 | Y10: 4500104347
A11: Seidel Gmbh&co Kg | B11: MB22 | C11: Zamak Gewicht | D11: POS030 | G11: 80000 | H11: 2026-02-25 | I11: =IFERROR(_xlfn.XLOOKUP(B11,Terméklista!$B$6:$B$105,Terméklista!$H$6:$H$105)," ") -> 0 | N11: =IFERROR(M11+(L11*30),"") -> 0 | Y11: 4500104347
A12: Seidel Gmbh&co Kg | C12: 0 | D12: MB44 szerszám | G12: 1 | H12: 2026-03-24 | I12: =IFERROR(_xlfn.XLOOKUP(B12,Terméklista!$B$6:$B$105,Terméklista!$H$6:$H$105)," ") -> 0 | N12: =IFERROR(M12+(L12*30),"") -> 0 | Y12: 4500104683
A13: Seidel Gmbh&co Kg | B13: MB44 | C13: 80 0230 018 001 01 02 | D13: POS020 | G13: 500 | H13: 2026-03-31 | I13: =IFERROR(_xlfn.XLOOKUP(B13,Terméklista!$B$6:$B$105,Terméklista!$H$6:$H$105)," ") -> 0 | N13: =IFERROR(M13+(L13*30),"") -> 0 | Y13: 4500104683
A14: Seidel Gmbh&co Kg | B14: MA51 | C14: Zamak Gewicht | D14: POS010, rendelés módosítás 2026.02.04én | G14: 50000 | H14: 2026-02-25 | I14: =IFERROR(_xlfn.XLOOKUP(B14,Terméklista!$B$6:$B$105,Terméklista!$H$6:$H$105)," ") -> 0 | J14: x | N14: =IFERROR(M14+(L14*30),"") -> 0 | Y14: 4500104784
A15: Systec Pos-Technology Gmbh | B15: Sperritzteil-2 | E15: M251070 Pos-10 | G15: 10000 | H15: 2026-03-23 | I15: =IFERROR(_xlfn.XLOOKUP(B15,Terméklista!$B$6:$B$105,Terméklista!$H$6:$H$105)," ") -> 0 | N15: =IFERROR(M15+(L15*30),"") -> 0 | Y15: 27366
A16: Inter-Metal Recycling Kft. | B16: Forgács Aluminium | E16: M251071 Pos-10 | G16: 5 | I16: =IFERROR(_xlfn.XLOOKUP(B16,Terméklista!$B$6:$B$105,Terméklista!$H$6:$H$105)," ") -> 0 | N16: =IFERROR(M16+(L16*30),"") -> 0
A17: Inter-Metal Recycling Kft. | B17: Forgács Rozsdamentés | E17: M251071 Pos-20 | G17: 1 | I17: =IFERROR(_xlfn.XLOOKUP(B17,Terméklista!$B$6:$B$105,Terméklista!$H$6:$H$105)," ") -> 0 | N17: =IFERROR(M17+(L17*30),"") -> 0
A18: Inter-Metal Recycling Kft. | B18: Forgács Vegyes | E18: M251071 Pos-30 | G18: 1 | I18: =IFERROR(_xlfn.XLOOKUP(B18,Terméklista!$B$6:$B$105,Terméklista!$H$6:$H$105)," ") -> 0 | N18: =IFERROR(M18+(L18*30),"") -> 0
A19: Ela Solutions Kft. | B19: 90ZA-ZK001-06 | G19: 1500 | H19: 2026-02-20 | I19: =IFERROR(_xlfn.XLOOKUP(B19,Terméklista!$B$6:$B$105,Terméklista!$H$6:$H$105)," ") -> 0 | N19: =IFERROR(M19+(L19*30),"") -> 0 | Y19: 6076
A20: Seidel Gmbh&co Kg | B20: MA51 | D20: POS020 | G20: 50000 | H20: 2026-03-16 | I20: =IFERROR(_xlfn.XLOOKUP(B20,Terméklista!$B$6:$B$105,Terméklista!$H$6:$H$105)," ") -> 0 | N20: =IFERROR(M20+(L20*30),"") -> 0 | Y20: 4500104784
A21: Seidel Gmbh&co Kg | B21: MA41 | D21: POS010 | G21: 50000 | H21: 2026-04-13 | I21: =IFERROR(_xlfn.XLOOKUP(B21,Terméklista!$B$6:$B$105,Terméklista!$H$6:$H$105)," ") -> 0 | N21: =IFERROR(M21+(L21*30),"") -> 0 | Y21: 4500105052
A22: Seidel Gmbh&co Kg | B22: MA66 | D22: POS010 | G22: 250000 | H22: 2026-06-01 | I22: =IFERROR(_xlfn.XLOOKUP(B22,Terméklista!$B$6:$B$105,Terméklista!$H$6:$H$105)," ") -> 0 | N22: =IFERROR(M22+(L22*30),"") -> 0 | Y22: 4500105053

Sheet Terméklista
A1: Ügyfél | B1: Termék rajzszáma | C1: Termék megnevezés | D1: Megjegyzés | E1: Fészekszáma | F1: Súly/db g | G1: Anyag | H1: Felületkezelés | I1: Ciklus idő | J1: Utómunka idő | K1: Utómunkák | L1: Doboz méret | M1: Doboz/db | N1: Doboz/Raklap | O1: Arktikál nr. | P1: Raktár | Q1: Engusz súly
A2: Arsisco AMO Pack LLC | B2: Fehér hüvely | E2: 4 | F2: 0.225 | G2: Műanyag | I2: 13 | Q2: 0.675
A3: Arsisco AMO Pack LLC | B3: Töltő sin | G3: Z414 | I3: 15
A4: Arsisco AMO Pack LLC | B4: Lánctalp | G4: Z414 | I4: 15
A5: Ela Solutions Kft. | B5: 90ZA-AD001-00 | C5: rúdadapter | D5: Logó | E5: 2 | F5: 21.6 | G5: Z410 | I5: 15
A6: Ela Solutions Kft. | B6: 90ZA-B001-06 | C6: zárbetét - 3mm | E6: 2 | F6: 14.85 | G6: Z410 | I6: 15
A7: Ela Solutions Kft. | B7: 90ZA-B003-06 | E7: 2 | F7: 15.6 | G7: Z410 | I7: 15
A8: Ela Solutions Kft. | B8: 90ZA-B004-06 | C8: zárbetét | E8: 2 | F8: 8.1 | G8: Z410 | I8: 15 | V8: {=TRANSPOSE(_xlfn._xlws.SORT(_xlfn.UNIQUE(Alkatrészek[Ügyfél])))} -> Arsisco AMO Pack LLC | W8: Ela Solutions Kft. | X8: Fasten Italia S.R.L | Y8: Inter-Metal Recycling Kft. | Z8: Ligeti Péter | AA8: R-Plast Manufacturing Kft | AB8: R-Szerkterv Kft. | AC8: Seidel Gmbh&co Kg | AD8: Systec Pos-Technology Gmbh
A9: Ela Solutions Kft. | B9: 90ZA-B007-04 | C9: zárbetét - 9,5mm 3szög | E9: 2 | F9: 12 | G9: Z410 | I9: 15 | V9: {=_xlfn._xlws.FILTER(Alkatrészek[Termék rajzszáma],Alkatrészek[Ügyfél]=V8,"")} -> Fehér hüvely | W9: {=_xlfn._xlws.FILTER(Alkatrészek[Termék rajzszáma],Alkatrészek[Ügyfél]=W8,"")} -> 90ZA-AD001-00 | X9: {=_xlfn._xlws.FILTER(Alkatrészek[Termék rajzszáma],Alkatrészek[Ügyfél]=X8,"")} -> corpoP6 nyitó | Y9: {=_xlfn._xlws.FILTER(Alkatrészek[Termék rajzszáma],Alkatrészek[Ügyfél]=Y8,"")} -> Forgács Aluminium | Z9: {=_xlfn._xlws.FILTER(Alkatrészek[Termék rajzszáma],Alkatrészek[Ügyfél]=Z8,"")} -> nyersanyag | AA9: {=_xlfn._xlws.FILTER(Alkatrészek[Termék rajzszáma],Alkatrészek[Ügyfél]=AA8,"")} -> Magasságállító | AB9: {=_xlfn._xlws.FILTER(Alkatrészek[Termék rajzszáma],Alkatrészek[Ügyfél]=AB8,"")} -> M 400-2 | AC9: {=_xlfn._xlws.FILTER(Alkatrészek[Termék rajzszáma],Alkatrészek[Ügyfél]=AC8,"")} -> B83 | AD9: {=_xlfn._xlws.FILTER(Alkatrészek[Termék megnevezés],Alkatrészek[Termék rajzszáma]=AD8,"")} | AE9: {=_xlfn._xlws.FILTER(Alkatrészek[Termék rajzszáma],Alkatrészek[Ügyfél]=AE8,"")} | AF9: {=_xlfn._xlws.FILTER(Alkatrészek[Termék rajzszáma],Alkatrészek[Ügyfél]=AF8,"")} | AG9: {=_xlfn._xlws.FILTER(Alkatrészek[Termék rajzszáma],Alkatrészek[Ügyfél]=AG8,"")}
A10: Ela Solutions Kft. | B10: 90ZA-B008-04 | E10: 2 | F10: 12.5 | G10: Z410 | I10: 15 | V10: Töltő sin | W10: 90ZA-B001-06 | X10: P6 body | Y10: Forgács Rozsdamentés | AA10: Szíj rövid | AB10: M 400-4 | AC10: B93 | AD10: {=_xlfn._xlws.FILTER(Alkatrészek[Termék megnevezés],Alkatrészek[Termék rajzszáma]=AD9,"")}
A11: Ela Solutions Kft. | B11: 90ZA-B009-04 | C11: Zárbetét 2x4-es sliccel | E11: 2 | F11: 17.4 | G11: Z410 | I11: 15 | V11: Lánctalp | W11: 90ZA-B003-06 | X11: YKK fogó | Y11: Forgács Vas | AA11: Szíj hosszú | AC11: M66 | AD11: {=_xlfn._xlws.FILTER(Alkatrészek[Termék megnevezés],Alkatrészek[Termék rajzszáma]=AD10,"")}
A12: Ela Solutions Kft. | B12: 90ZA-B010-04 | C12: zárbetét sliccel | E12: 2 | F12: 7 | G12: Z410 | I12: 15 | V12: Sín 5 | W12: 90ZA-B004-06 | X12: P6 body szerszám | Y12: Forgács Vegyes | AA12: Pánt | AC12: M70 | AD12: {=_xlfn._xlws.FILTER(Alkatrészek[Termék megnevezés],Alkatrészek[Termék rajzszáma]=AD11,"")}
A13: Ela Solutions Kft. | B13: 90ZA-B012-06 | C13: zárbetét - 8mm | E13: 2 | F13: 12.2 | G13: Z410 | I13: 15 | W13: 90ZA-B007-04 | Y13: Vas lemez hulladék | AA13: Szíj doboz | AC13: M83 | AD13: {=_xlfn._xlws.FILTER(Alkatrészek[Termék megnevezés],Alkatrészek[Termék rajzszáma]=AD12,"")}
A14: Ela Solutions Kft. | B14: 90ZA-H001-06 | C14: zárház | E14: 2 | F14: 24.5 | G14: Z410 | I14: 15 | W14: 90ZA-B008-04 | Y14: Csöpedék - Horgany | AC14: MA41 | AD14: {=_xlfn._xlws.FILTER(Alkatrészek[Termék megnevezés],Alkatrészek[Termék rajzszáma]=AD13,"")}
A15: Ela Solutions Kft. | B15: 90ZA-H002-06 | C15: zárház | E15: 2 | F15: 18.5 | G15: Z410 | I15: 15 | W15: 90ZA-B009-04 | Y15: Réz | AC15: MA51 | AD15: {=_xlfn._xlws.FILTER(Alkatrészek[Termék megnevezés],Alkatrészek[Termék rajzszáma]=AD14,"")}
A16: Ela Solutions Kft. | B16: 90ZA-H005-04 | C16: zárház | E16: 2 | F16: 8.3 | G16: Z410 | I16: 15 | W16: 90ZA-B010-04 | AC16: MA62 | AD16: {=_xlfn._xlws.FILTER(Alkatrészek[Termék megnevezés],Alkatrészek[Termék rajzszáma]=AD15,"")}
A17: Ela Solutions Kft. | B17: 90ZA-H020-06 | C17: lakattal zárható zárház | E17: 2 | F17: 92.53 | G17: Z410 | I17: 15 | W17: 90ZA-B012-06 | AC17: MA66 | AD17: {=_xlfn._xlws.FILTER(Alkatrészek[Termék megnevezés],Alkatrészek[Termék rajzszáma]=AD16,"")}
A18: Ela Solutions Kft. | B18: 90ZA-H021-06 | C18: lakattal zárható zárház | E18: 2 | F18: 92.56 | G18: Z410 | I18: 15 | W18: 90ZA-H001-06 | AC18: MB01 | AD18: {=_xlfn._xlws.FILTER(Alkatrészek[Termék megnevezés],Alkatrészek[Termék rajzszáma]=AD17,"")}
A19: Ela Solutions Kft. | B19: 90ZA-HT001-00 | C19: anya M22x1,5 | E19: 6 | F19: 8.3 | G19: Z410 | I19: 15 | W19: 90ZA-H002-06 | AC19: MB22 | AD19: {=_xlfn._xlws.FILTER(Alkatrészek[Termék megnevezés],Alkatrészek[Termék rajzszáma]=AD18,"")}
A20: Ela Solutions Kft. | B20: 90ZA-HT001-00 | C20: anya M22x1,5 (30.000 db) | E20: 6 | F20: 8.3 | G20: Z410 | I20: 15 | W20: 90ZA-H005-04 | AC20: MB44 | AD20: {=_xlfn._xlws.FILTER(Alkatrészek[Termék megnevezés],Alkatrészek[Termék rajzszáma]=AD19,"")}
A21: Ela Solutions Kft. | B21: 90ZA-HT002-00 | C21: anya M16x1 | E21: 6 | F21: 2.5 | G21: Z410 | I21: 15 | W21: 90ZA-H020-06 | AD21: {=_xlfn._xlws.FILTER(Alkatrészek[Termék megnevezés],Alkatrészek[Termék rajzszáma]=AD20,"")}
A22: Ela Solutions Kft. | B22: 90ZA-HT004-00 | E22: 4 | F22: 5.2 | G22: Z410 | I22: 15 | W22: 90ZA-H021-06 | AD22: {=_xlfn._xlws.FILTER(Alkatrészek[Termék megnevezés],Alkatrészek[Termék rajzszáma]=AD21,"")}
A23: Ela Solutions Kft. | B23: 90ZA-NY001-00 | C23: fogasnyelv | E23: 2 | F23: 14.9 | G23: Z410 | I23: 15 | W23: 90ZA-HT001-00 | AD23: {=_xlfn._xlws.FILTER(Alkatrészek[Termék megnevezés],Alkatrészek[Termék rajzszáma]=AD22,"")}
A24: Ela Solutions Kft. | B24: 90ZA-ZK001-06 | E24: 2 | F24: 22.34 | G24: Z410 | I24: 15 | W24: 90ZA-HT001-00 | AD24: {=_xlfn._xlws.FILTER(Alkatrészek[Termék megnevezés],Alkatrészek[Termék rajzszáma]=AD23,"")}
A25: Ela Solutions Kft. | B25: 90ZA-ZK006-06 | C25: kulcs - 8mm | E25: 2 | F25: 23.6 | G25: Z410 | I25: 15 | W25: 90ZA-HT002-00 | AD25: {=_xlfn._xlws.FILTER(Alkatrészek[Termék megnevezés],Alkatrészek[Termék rajzszáma]=AD24,"")}
A26: Ela Solutions Kft. | B26: 90ZA-ZK007-06 | C26: kulcs 10mm 3szög | E26: 2 | F26: 25.3 | G26: Z410 | I26: 15 | W26: 90ZA-HT004-00 | AD26: {=_xlfn._xlws.FILTER(Alkatrészek[Termék megnevezés],Alkatrészek[Termék rajzszáma]=AD25,"")}
A27: Ela Solutions Kft. | B27: 90ZA-ZK008-06 | C27: kiskulcs - 3mm | E27: 2 | F27: 22.8 | G27: Z410 | I27: 15 | W27: 90ZA-NY001-00 | AD27: {=_xlfn._xlws.FILTER(Alkatrészek[Termék megnevezés],Alkatrészek[Termék rajzszáma]=AD26,"")}
A28: Ela Solutions Kft. | B28: 90ZA-ZK009-06 | E28: 2 | F28: 21.7 | G28: Z410 | I28: 15 | W28: 90ZA-ZK001-06 | AD28: {=_xlfn._xlws.FILTER(Alkatrészek[Termék megnevezés],Alkatrészek[Termék rajzszáma]=AD27,"")}
A29: Ela Solutions Kft. | B29: 90ZA-ZK010-06 | C29: kereszt kulcs | E29: 1 | F29: 60.9 | G29: Z410 | I29: 15 | W29: 90ZA-ZK006-06 | AD29: {=_xlfn._xlws.FILTER(Alkatrészek[Termék megnevezés],Alkatrészek[Termék rajzszáma]=AD28,"")}
A30: Ela Solutions Kft. | B30: 90ZA-ZK011-06 | C30: nagykulcs - 3mm | E30: 2 | F30: 47.55 | G30: Z410 | I30: 15 | W30: 90ZA-ZK007-06 | AD30: {=_xlfn._xlws.FILTER(Alkatrészek[Termék megnevezés],Alkatrészek[Termék rajzszáma]=AD29,"")}
A31: Ela Solutions Kft. | B31: 90ZA-ZK012-06 | C31: nagykulcs - 5mm | E31: 2 | F31: 47.3 | G31: Z410 | I31: 15 | W31: 90ZA-ZK008-06 | AD31: {=_xlfn._xlws.FILTER(Alkatrészek[Termék megnevezés],Alkatrészek[Termék rajzszáma]=AD30,"")}
A32: Ela Solutions Kft. | B32: 90ZA-ZS001-06 | C32: Zsanérbelső | E32: 2 | F32: 15 | G32: Z410 | I32: 15 | W32: 90ZA-ZK009-06 | AD32: {=_xlfn._xlws.FILTER(Alkatrészek[Termék megnevezés],Alkatrészek[Termék rajzszáma]=AD31,"")}
A33: Ela Solutions Kft. | B33: 90ZA-ZS002-06 | C33: Zsanérkülső | E33: 2 | F33: 20.8 | G33: Z410 | I33: 15 | W33: 90ZA-ZK010-06 | AD33: {=_xlfn._xlws.FILTER(Alkatrészek[Termék megnevezés],Alkatrészek[Termék rajzszáma]=AD32,"")}
A34: Ela Solutions Kft. | B34: 90ZA-ZS004-00 | C34: zsanértest | E34: 2 | F34: 70 | G34: Z410 | I34: 15 | W34: 90ZA-ZK011-06 | AD34: {=_xlfn._xlws.FILTER(Alkatrészek[Termék megnevezés],Alkatrészek[Termék rajzszáma]=AD33,"")}
A35: Ela Solutions Kft. | B35: 90ZA-ZS005-06 | C35: zsanértest | E35: 2 | F35: 81.72 | G35: Z410 | I35: 15 | W35: 90ZA-ZK012-06 | AD35: {=_xlfn._xlws.FILTER(Alkatrészek[Termék megnevezés],Alkatrészek[Termék rajzszáma]=AD34,"")}
A36: Ela Solutions Kft. | B36: 90ZA-ZS013-06 | C36: zsanértest | E36: 2 | F36: 52.6 | G36: Z410 | I36: 15 | W36: 90ZA-ZS001-06 | AD36: {=_xlfn._xlws.FILTER(Alkatrészek[Termék megnevezés],Alkatrészek[Termék rajzszáma]=AD35,"")}
A37: Ela Solutions Kft. | B37: 90ZA-ZS016-06 | C37: engusz letörés csiszolása | E37: 1 | F37: 0 | G37: Z410 | I37: 15 | W37: 90ZA-ZS002-06 | AD37: {=_xlfn._xlws.FILTER(Alkatrészek[Termék megnevezés],Alkatrészek[Termék rajzszáma]=AD36,"")}
A38: Ela Solutions Kft. | B38: 90ZA-ZS016-06 | C38: menet készítés | E38: 2 | F38: 0 | G38: Z410 | I38: 15 | W38: 90ZA-ZS004-00 | AD38: {=_xlfn._xlws.FILTER(Alkatrészek[Termék megnevezés],Alkatrészek[Termék rajzszáma]=AD37,"")}
A39: Ela Solutions Kft. | B39: 90ZA-ZS016-06 | C39: öntés, koptatás, mosás | E39: 1 | F39: 0 | G39: Z410 | I39: 15 | W39: 90ZA-ZS005-06 | AD39: {=_xlfn._xlws.FILTER(Alkatrészek[Termék megnevezés],Alkatrészek[Termék rajzszáma]=AD38,"")}
A40: Ela Solutions Kft. | B40: 90ZA-ZS016-06 | C40: zsanérbelső | E40: 1 | F40: 206 | G40: Z410 | I40: 15 | W40: 90ZA-ZS013-06 | AD40: {=_xlfn._xlws.FILTER(Alkatrészek[Termék megnevezés],Alkatrészek[Termék rajzszáma]=AD39,"")}
...

Sheet Céglista
A1: Vevő név | B1: Szállító Nyelve | C1: Város | D1: Irányítószám | E1: Utca, házszám | F1: Ország | G1: Cím | H1: Adószám | I1: Vevő név2
